<?xml version="1.0" encoding="UTF-8"?>
<robot name="Robot">
    <link name="arm1">
        <inertial>
            <origin rpy="0.00000000 0.00000000 0.00000000" xyz="0.00000000 0.00000000 0.00000000"/>
            <mass value="1.00000000"/>
            <inertia ixx="1.00000000" ixy="0.00000000" ixz="0.00000000" iyy="1.00000000" iyz="0.00000000" izz="1.00000000"/>
        </inertial>
        <collision>
            <origin rpy="0.00000000 0.00000000 0.00000000" xyz="0.50000000 0.25000000 0.00000000"/>
            <geometry>
                <box size="0.05000000 0.10000000 1.50000000"/>
            </geometry>
        </collision>
    </link>
    <link name="arm2">
        <inertial>
            <origin rpy="0.00000000 0.00000000 0.00000000" xyz="0.00000000 0.00000000 0.00000000"/>
            <mass value="1.00000000"/>
            <inertia ixx="1.00000000" ixy="0.00000000" ixz="0.00000000" iyy="1.00000000" iyz="0.00000000" izz="1.00000000"/>
        </inertial>
        <collision>
            <origin rpy="0.00000000 0.00000000 0.00000000" xyz="0.50000000 -0.25000000  0.00000000"/>
            <geometry>
                <box size="0.05000000 0.10000000 1.50000000"/>
            </geometry>
        </collision>
    </link>
    <link name="arm3">
        <inertial>
            <origin rpy="0.00000000 0.00000000 0.00000000" xyz="0.00000000 0.00000000 0.00000000"/>
            <mass value="1.00000000"/>
            <inertia ixx="1.00000000" ixy="0.00000000" ixz="0.00000000" iyy="1.00000000" iyz="0.00000000" izz="1.00000000"/>
        </inertial>
        <collision>
            <origin rpy="0.00000000 0.00000000 0.00000000" xyz="-0.25000000  0.75000000  0.00000000"/>
            <geometry>
                <box size="0.10000000 0.05000000 1.50000000"/>
            </geometry>
        </collision>
    </link>
    <link name="arm4">
        <inertial>
            <origin rpy="0.00000000 0.00000000 0.00000000" xyz="0.00000000 0.00000000 0.00000000"/>
            <mass value="1.00000000"/>
            <inertia ixx="1.00000000" ixy="0.00000000" ixz="0.00000000" iyy="1.00000000" iyz="0.00000000" izz="1.00000000"/>
        </inertial>
        <collision>
            <origin rpy="0.00000000 0.00000000 0.00000000" xyz="-0.25000000 -0.75000000  0.00000000"/>
            <geometry>
                <box size="0.10000000 0.05000000 1.50000000"/>
            </geometry>
        </collision>
    </link>
    <link name="base">
        <inertial>
            <mass value="0"/>
            <inertia ixx="0" ixy="0" ixz="0" iyy="0" iyz="0" izz="0"/>
        </inertial>
    </link>
    <link name="fixed_base">
        <inertial>
            <origin rpy="0.00000000 0.00000000 0.00000000" xyz="0.00000000 0.00000000 0.00000000"/>
            <mass value="1.00000000"/>
            <inertia ixx="1.00000000" ixy="0.00000000" ixz="0.00000000" iyy="1.00000000" iyz="0.00000000" izz="1.00000000"/>
        </inertial>
        <collision>
            <origin rpy="0.00000000 0.00000000 0.00000000" xyz="0.00000000  0.00000000 -0.75000000"/>
            <geometry>
                <box size="1.00000000 1.50000000 0.05000000"/>
            </geometry>
        </collision>
    </link>
    <link name="fixed_base2">
        <inertial>
            <origin rpy="0.00000000 0.00000000 0.00000000" xyz="0.00000000 0.00000000 0.00000000"/>
            <mass value="1.00000000"/>
            <inertia ixx="1.00000000" ixy="0.00000000" ixz="0.00000000" iyy="1.00000000" iyz="0.00000000" izz="1.00000000"/>
        </inertial>
        <collision>
            <origin rpy="0.00000000 0.00000000 0.00000000" xyz="0.00000000 0.00000000 0.75000000"/>
            <geometry>
                <box size="1.00000000 1.50000000 0.05000000"/>
            </geometry>
        </collision>
    </link>
    <link name="gripper">
        <inertial>
            <origin rpy="0.00000000 0.00000000 0.00000000" xyz="0.00000000 0.00000000 0.00000000"/>
            <mass value="1.00000000"/>
            <inertia ixx="1.00000000" ixy="0.00000000" ixz="0.00000000" iyy="1.00000000" iyz="0.00000000" izz="1.00000000"/>
        </inertial>
        <collision>
            <origin rpy="0.00000000 0.00000000 0.00000000" xyz="0.00000000 0.00000000 0.00000000"/>
            <geometry>
                <cylinder radius="0.05000000" length="0.04000000"/>
            </geometry>
        </collision>
    </link>
    <link name="gripper_base">
        <inertial>
            <origin rpy="0.00000000 0.00000000 0.00000000" xyz="0.00000000 0.00000000 0.00000000"/>
            <mass value="1.00000000"/>
            <inertia ixx="1.00000000" ixy="0.00000000" ixz="0.00000000" iyy="1.00000000" iyz="0.00000000" izz="1.00000000"/>
        </inertial>
        <collision>
            <origin rpy="0.00000000 0.00000000 0.00000000" xyz="0.00000000 0.00000000 0.02000000"/>
            <geometry>
                <box size="0.50000000 0.50000000 0.01000000"/>
            </geometry>
        </collision>
    </link>
    <link name="link1">
        <inertial>
            <origin rpy="0.00000000 0.00000000 0.00000000" xyz="0.00000000 0.00000000 0.00000000"/>
            <mass value="1.00000000"/>
            <inertia ixx="1.00000000" ixy="0.00000000" ixz="0.00000000" iyy="1.00000000" iyz="0.00000000" izz="1.00000000"/>
        </inertial>
        <collision>
            <origin rpy="0.00000000 0.52359878 0.00000000" xyz="0.33000000 0.25000000 0.22000000"/>
            <geometry>
                <box size="0.05000000 0.05000000 0.47169906"/>
            </geometry>
        </collision>
    </link>
    <link name="link2">
        <inertial>
            <origin rpy="0.00000000 0.00000000 0.00000000" xyz="0.00000000 0.00000000 0.00000000"/>
            <mass value="1.00000000"/>
            <inertia ixx="1.00000000" ixy="0.00000000" ixz="0.00000000" iyy="1.00000000" iyz="0.00000000" izz="1.00000000"/>
        </inertial>
        <collision>
            <origin rpy="0.00000000 0.52359878 0.00000000" xyz="0.33000000 -0.25000000  0.22000000"/>
            <geometry>
                <box size="0.05000000 0.05000000 0.47169906"/>
            </geometry>
        </collision>
    </link>
    <link name="link3">
        <inertial>
            <origin rpy="0.00000000 0.00000000 0.00000000" xyz="0.00000000 0.00000000 0.00000000"/>
            <mass value="1.00000000"/>
            <inertia ixx="1.00000000" ixy="0.00000000" ixz="0.00000000" iyy="1.00000000" iyz="0.00000000" izz="1.00000000"/>
        </inertial>
        <collision>
            <origin rpy="-1.04719755  0.00000000  0.00000000" xyz="-0.25000000  0.48000000  0.17000000"/>
            <geometry>
                <box size="0.06000000 0.05000000 0.60000000"/>
            </geometry>
        </collision>
    </link>
    <link name="link4">
        <inertial>
            <origin rpy="0.00000000 0.00000000 0.00000000" xyz="0.00000000 0.00000000 0.00000000"/>
            <mass value="1.00000000"/>
            <inertia ixx="1.00000000" ixy="0.00000000" ixz="0.00000000" iyy="1.00000000" iyz="0.00000000" izz="1.00000000"/>
        </inertial>
        <collision>
            <origin rpy="1.04719755 0.00000000 0.00000000" xyz="-0.25000000 -0.48000000  0.17000000"/>
            <geometry>
                <box size="0.06000000 0.05000000 0.60000000"/>
            </geometry>
        </collision>
    </link>
    <joint name="base_joint" type="fixed">
        <parent link="base"/>
        <child link="fixed_base"/>
        <origin rpy="0.00000000 0.00000000 0.00000000" xyz="0.00000000 0.00000000 0.00000000"/>
        <axis xyz="100"/>
    </joint>
    <joint name="base_joint2" type="fixed">
        <parent link="fixed_base"/>
        <child link="fixed_base2"/>
        <origin rpy="0.00000000 0.00000000 0.00000000" xyz="0.00000000 0.00000000 0.00000000"/>
        <axis xyz="100"/>
    </joint>
    <joint name="gripper_base" type="fixed">
        <parent link="link4"/>
        <child link="gripper_base"/>
        <origin rpy="0.00000000 0.00000000 0.00000000" xyz="0.00000000 0.00000000 0.00000000"/>
        <axis xyz="100"/>
    </joint>
    <joint name="gripper_joint" type="revolute">
        <parent link="gripper_base"/>
        <child link="gripper"/>
        <origin rpy="0.00000000 0.00000000 0.00000000" xyz="0.00000000 0.00000000 0.00000000"/>
        <axis xyz="0.00000000 1.00000000 0.00000000"/>
        <limit lower="-3.14159265" upper="3.14159265" effort="0" velocity="0"/>
    </joint>
    <joint name="jnt1" type="prismatic">
        <parent link="fixed_base2"/>
        <child link="arm1"/>
        <origin rpy="0.00000000 0.00000000 0.00000000" xyz="0.00000000 0.00000000 0.00000000"/>
        <axis xyz="1.00000000 0.00000000 0.00000000"/>
        <limit lower="-0.50000000" upper="0.50000000" effort="0" velocity="0"/>
    </joint>
    <joint name="jnt1_2" type="fixed">
        <parent link="arm1"/>
        <child link="link1"/>
        <origin rpy="0.00000000 0.00000000 0.00000000" xyz="0.00000000 0.00000000 0.00000000"/>
        <axis xyz="100"/>
    </joint>
    <joint name="jnt2" type="prismatic">
        <parent link="link1"/>
        <child link="arm2"/>
        <origin rpy="0.00000000 0.00000000 0.00000000" xyz="0.00000000 0.00000000 0.00000000"/>
        <axis xyz="1.00000000 0.00000000 0.00000000"/>
        <limit lower="-0.50000000" upper="0.50000000" effort="0" velocity="0"/>
    </joint>
    <joint name="jnt2_2" type="fixed">
        <parent link="arm2"/>
        <child link="link2"/>
        <origin rpy="0.00000000 0.00000000 0.00000000" xyz="0.00000000 0.00000000 0.00000000"/>
        <axis xyz="100"/>
    </joint>
    <joint name="jnt3" type="prismatic">
        <parent link="link2"/>
        <child link="arm3"/>
        <origin rpy="0.00000000 0.00000000 0.00000000" xyz="0.00000000 0.00000000 0.00000000"/>
        <axis xyz="1.00000000 0.00000000 0.00000000"/>
        <limit lower="-0.50000000" upper="0.50000000" effort="0" velocity="0"/>
    </joint>
    <joint name="jnt3_2" type="fixed">
        <parent link="arm3"/>
        <child link="link3"/>
        <origin rpy="0.00000000 0.00000000 0.00000000" xyz="0.00000000 0.00000000 0.00000000"/>
        <axis xyz="100"/>
    </joint>
    <joint name="jnt4" type="prismatic">
        <parent link="link3"/>
        <child link="arm4"/>
        <origin rpy="0.00000000 0.00000000 0.00000000" xyz="0.00000000 0.00000000 0.00000000"/>
        <axis xyz="1.00000000 0.00000000 0.00000000"/>
        <limit lower="-0.50000000" upper="0.50000000" effort="0" velocity="0"/>
    </joint>
    <joint name="jnt4_2" type="fixed">
        <parent link="arm4"/>
        <child link="link4"/>
        <origin rpy="0.00000000 0.00000000 0.00000000" xyz="0.00000000 0.00000000 0.00000000"/>
        <axis xyz="100"/>
    </joint>
</robot>
